Workbook

Sheet Customer Data
A1: Invoice | B1: StockCode | C1: Description | D1: Quantity | E1: InvoiceDate | F1: Price | G1: Customer ID | H1: Country
A2: 489434 | B2: 22041 | C2: RECORD FRAME 7" SINGLE SIZE | D2: 48 | E2: 40148.323 | F2: 2.1 | G2: 13085 | H2: United Kingdom
A3: 489435 | B3: 22195 | C3: HEART MEASURING SPOONS LARGE | D3: 24 | E3: 40148.324 | F3: 1.65 | G3: 13085 | H3: United Kingdom
A4: 489436 | B4: 48173C | C4: DOOR MAT BLACK FLOCK | D4: 10 | E4: 40148.379 | F4: 5.95 | G4: 13078 | H4: United Kingdom
A5: 489437 | B5: 22143 | C5: CHRISTMAS CRAFT HEART DECORATIONS | D5: 6 | E5: 40148.381 | F5: 2.1 | G5: 15362 | H5: United Kingdom
A6: 489437 | B6: 22143 | C6: CHRISTMAS CRAFT HEART DECORATIONS | D6: 6 | E6: 40148.381 | F6: 2.1 | G6: 15362 | H6: United Kingdom
A7: 489438 | B7: 21252 | C7: SET OF MEADOW FLOWER STICKERS | D7: 30 | E7: 40148.392 | F7: 1.69 | G7: 18102 | H7: United Kingdom
A8: 489439 | B8: 22138 | C8: BAKING SET 9 PIECE RETROSPOT | D8: 9 | E8: 40148.394 | F8: 4.95 | G8: 12682 | H8: France
A9: 489440 | B9: 22350 | C9: CAT BOWL | D9: 8 | E9: 40148.405 | F9: 2.55 | G9: 18087 | H9: United Kingdom
A10: 489441 | B10: 22138 | C10: BAKING SET 9 PIECE RETROSPOT | D10: 6 | E10: 40148.406 | F10: 4.25 | G10: 18087 | H10: United Kingdom
A11: 489442 | B11: 22111 | C11: SCOTTIE DOG HOT WATER BOTTLE | D11: 3 | E11: 40148.407 | F11: 4.95 | G11: 13635 | H11: United Kingdom
A12: 489443 | B12: 82580 | C12: BATHROOM METAL SIGN | D12: 12 | E12: 40148.41 | F12: 0.55 | G12: 14110 | H12: United Kingdom
A13: 489444 | B13: POST | C13: POSTAGE | D13: 1 | E13: 40148.413 | F13: -141 | G13: 12636 | H13: USA
A14: 489445 | B14: 35916B | C14: BLUE FELT HANGING HEART W FLOWER | D14: 12 | E14: 40148.415 | F14: 0.85 | G14: 17519 | H14: United Kingdom
A15: 489446 | B15: 21733 | C15: RED HANGING HEART T-LIGHT HOLDER | D15: 32 | E15: 40148.421 | F15: 2.55 | G15: 13758 | H15: United Kingdom
A16: 489447 | B16: POST | C16: POSTAGE | D16: 1 | E16: 40148.424 | F16: -130 | G16: 12362 | H16: Belgium
A17: 489448 | B17: 20823 | C17: GOLD WINE GOBLET | D17: 48 | E17: 40148.429 | F17: 4.25 | G17: 15413 | H17: United Kingdom
A18: 489450 | B18: 21896 | C18: POTTING SHED TWINE | D18: 6 | E18: 40148.442 | F18: 2.1 | G18: 16321 | H18: Australia
A19: 489460 | B19: 21977 | C19: PACK OF 60 PINK PAISLEY CAKE CASES | D19: 24 | E19: 40148.449 | F19: 0.55 | G19: 16167 | H19: United Kingdom
A20: 489461 | B20: 21248 | C20: DOOR HANGER MUM + DADS ROOM | D20: 12 | E20: 40148.451 | F20: 1.45 | G20: 17865 | H20: United Kingdom
A21: 489462 | B21: 90200E | C21: GREEN SWEETHEART BRACELET | D21: 3 | E21: 40148.451 | F21: 4.25 | G21: 17592 | H21: United Kingdom
A22: 489462 | B22: 90185C | C22: BLACK DIAMANTE EXPANDABLE RING | D22: 3 | E22: 40148.451 | F22: 4.25 | G22: 17592 | H22: United Kingdom
A23: 489462 | B23: 90185C | C23: BLACK DIAMANTE EXPANDABLE RING | D23: 3 | E23: 40148.451 | F23: 4.25 | G23: 17592 | H23: United Kingdom
A24: 489464 | B24: 21733 | C24: 85123a mixed | D24: -96 | E24: 40148.453 | F24: 0 | H24: United Kingdom
A25: 489465 | B25: 21707 | C25: FOLDING UMBRELLA , BLACK/BLUE SPOT | D25: 12 | E25: 40148.453 | F25: 4.95 | G25: 13767 | H25: United Kingdom
A26: 489467 | B26: 85123A | C26: 21733 mixed | D26: -192 | E26: 40148.453 | F26: 0 | H26: United Kingdom
A27: 489488 | B27: 84032A | C27: CHARLIE+LOLA PINK HOT WATER BOTTLE | D27: 1 | E27: 40148.458 | F27: 2.95 | G27: 17238 | H27: United Kingdom
A28: 489505 | B28: 48185 | C28: DOOR MAT FAIRY CAKE | D28: 10 | E28: 40148.47 | F28: 5.95 | G28: 15712 | H28: United Kingdom
A29: 489514 | B29: 47591D | C29: PINK FAIRY CAKE CHILD'S APRON | D29: 50 | E29: 40148.473 | F29: 1.65 | G29: 15311 | H29: United Kingdom
A30: 489517 | B30: 16207A | C30: PINK STRAWBERRY HANDBAG | D30: 2 | E30: 40148.482 | F30: 2.95 | G30: 16329 | H30: United Kingdom
A31: 489519 | B31: 22276 | C31: WASH BAG VINTAGE ROSE PAISLEY | D31: 6 | E31: 40148.484 | F31: 2.55 | G31: 17700 | H31: United Kingdom
A32: 489520 | B32: 35751C | C32: PURPLE CURRENT CANDLE RING | D32: 12 | E32: 40148.487 | F32: 0.75 | G32: 14911 | H32: EIRE
A33: 489521 | B33: 21646 | D33: -50 | E33: 40148.489 | F33: 0 | H33: United Kingdom
A34: 489522 | B34: 72760B | C34: VINTAGE CREAM 3 BASKET CAKE STAND | D34: 1 | E34: 40148.49 | F34: 9.95 | G34: 15998 | H34: United Kingdom
A35: 489523 | B35: 84879 | C35: ASSORTED COLOUR BIRD ORNAMENT | D35: 800 | E35: 40148.49 | F35: 1.45 | G35: 12931 | H35: United Kingdom
A36: 489525 | B36: 85226C | C36: BLUE PULL BACK RACING CAR | D36: 1 | E36: 40148.492 | F36: 0.55 | G36: 13293 | H36: United Kingdom
A37: 489525 | B37: 85226C | C37: BLUE PULL BACK RACING CAR | D37: 1 | E37: 40148.492 | F37: 0.55 | G37: 13293 | H37: United Kingdom
A38: 489526 | B38: 85049E | C38: SCANDINAVIAN REDS RIBBONS | D38: 12 | E38: 40148.493 | F38: 1.25 | G38: 12533 | H38: Germany
A39: 489529 | B39: 22300 | C39: COFFEE MUG DOG + BALL DESIGN | D39: 6 | E39: 40148.494 | F39: 2.55 | G39: 17984 | H39: United Kingdom
A40: 489531 | B40: 21034 | C40: REX CASH+CARRY JUMBO SHOPPER | D40: 1 | E40: 40148.498 | F40: 0.95 | G40: 14871 | H40: United Kingdom
...

Sheet Clean Data
A1: Invoice | B1: StockCode | C1: Description | D1: Quantity | E1: InvoiceDate | F1: Time | G1: Price | H1: Customer ID | I1: Country | J1: Revenue
A2: 489443 | B2: 82580 | C2: BATHROOM METAL SIGN | D2: 12 | E2: 40148.41 | F2: 9 AM | G2: 0.55 | H2: 14110 | I2: United Kingdom | J2: =D2*G2 -> 6.6 | L2: Cleaning Logic:
A3: 489460 | B3: 21977 | C3: PACK OF 60 PINK PAISLEY CAKE CASES | D3: 24 | E3: 40148.449 | F3: 10 AM | G3: 0.55 | H3: 16167 | I3: United Kingdom | J3: =D3*G3 -> 13.2 | L3: Remove the duplicate records
A4: 489525 | B4: 85226C | C4: BLUE PULL BACK RACING CAR | D4: 1 | E4: 40148.492 | F4: 11 AM | G4: 0.55 | H4: 13293 | I4: United Kingdom | J4: =D4*G4 -> 0.55 | L4: Converted Excel date serial numbers to readable date-time format
A5: 489520 | B5: 35751C | C5: PURPLE CURRENT CANDLE RING | D5: 12 | E5: 40148.487 | F5: 11 AM | G5: 0.75 | H5: 14911 | I5: EIRE | J5: =D5*G5 -> 9 | L5: Removed all cancelled orders (C-prefixed invoices)
A6: 489445 | B6: 35916B | C6: BLUE FELT HANGING HEART W FLOWER | D6: 12 | E6: 40148.415 | F6: 9 AM | G6: 0.85 | H6: 17519 | I6: United Kingdom | J6: =D6*G6 -> 10.2 | L6: Excluded postage, refunds, and zero-value transactions
A7: 489532 | B7: 85231E | C7: STRAWBERRY SCENTED SET/9 T-LIGHTS | D7: 12 | E7: 40148.499 | F7: 11 AM | G7: 0.85 | H7: 13394 | I7: United Kingdom | J7: =D7*G7 -> 10.2 | L7: Make 2 calculated columns Time & Revenue
A8: 489533 | B8: 84970S | C8: HANGING HEART ZINC T-LIGHT HOLDER | D8: 12 | E8: 40148.501 | F8: 12 PM | G8: 0.85 | H8: 16011 | I8: United Kingdom | J8: =D8*G8 -> 10.2
A9: 489531 | B9: 21034 | C9: REX CASH+CARRY JUMBO SHOPPER | D9: 1 | E9: 40148.498 | F9: 11 AM | G9: 0.95 | H9: 14871 | I9: United Kingdom | J9: =D9*G9 -> 0.95
A10: 489449 | B10: 21871 | C10: SAVE THE PLANET MUG | D10: 12 | E10: 40148.44 | F10: 10 AM | G10: 1.25 | H10: 16321 | I10: Australia | J10: =D10*G10 -> 15
A11: 489526 | B11: 85049E | C11: SCANDINAVIAN REDS RIBBONS | D11: 12 | E11: 40148.493 | F11: 11 AM | G11: 1.25 | H11: 12533 | I11: Germany | J11: =D11*G11 -> 15
A12: 489461 | B12: 21248 | C12: DOOR HANGER MUM + DADS ROOM | D12: 12 | E12: 40148.451 | F12: 10 AM | G12: 1.45 | H12: 17865 | I12: United Kingdom | J12: =D12*G12 -> 17.4
A13: 489523 | B13: 84879 | C13: ASSORTED COLOUR BIRD ORNAMENT | D13: 800 | E13: 40148.49 | F13: 11 AM | G13: 1.45 | H13: 12931 | I13: United Kingdom | J13: =D13*G13 -> 1160
A14: 489435 | B14: 22195 | C14: HEART MEASURING SPOONS LARGE | D14: 24 | E14: 40148.324 | F14: 7 AM | G14: 1.65 | H14: 13085 | I14: United Kingdom | J14: =D14*G14 -> 39.6
A15: 489514 | B15: 47591D | C15: PINK FAIRY CAKE CHILD'S APRON | D15: 50 | E15: 40148.473 | F15: 11 AM | G15: 1.65 | H15: 15311 | I15: United Kingdom | J15: =D15*G15 -> 82.5
A16: 489527 | B16: 21173 | C16: LOO ROLL METAL SIGN | D16: 12 | E16: 40148.493 | F16: 11 AM | G16: 1.65 | H16: 16128 | I16: United Kingdom | J16: =D16*G16 -> 19.8
A17: 489438 | B17: 21252 | C17: SET OF MEADOW FLOWER STICKERS | D17: 30 | E17: 40148.392 | F17: 9 AM | G17: 1.69 | H17: 18102 | I17: United Kingdom | J17: =D17*G17 -> 50.7
A18: 489434 | B18: 22041 | C18: RECORD FRAME 7" SINGLE SIZE | D18: 48 | E18: 40148.323 | F18: 7 AM | G18: 2.1 | H18: 13085 | I18: United Kingdom | J18: =D18*G18 -> 100.8
A19: 489437 | B19: 22143 | C19: CHRISTMAS CRAFT HEART DECORATIONS | D19: 6 | E19: 40148.381 | F19: 9 AM | G19: 2.1 | H19: 15362 | I19: United Kingdom | J19: =D19*G19 -> 12.6
A20: 489450 | B20: 21896 | C20: POTTING SHED TWINE | D20: 6 | E20: 40148.442 | F20: 10 AM | G20: 2.1 | H20: 16321 | I20: Australia | J20: =D20*G20 -> 12.6
A21: 489476 | B21: 22149 | C21: FELTCRAFT 6 FLOWER FRIENDS | D21: 6 | E21: 40148.455 | F21: 10 AM | G21: 2.1 | H21: 13293 | I21: United Kingdom | J21: =D21*G21 -> 12.6
A22: 489440 | B22: 22350 | C22: CAT BOWL | D22: 8 | E22: 40148.405 | F22: 9 AM | G22: 2.55 | H22: 18087 | I22: United Kingdom | J22: =D22*G22 -> 20.4
A23: 489446 | B23: 21733 | C23: RED HANGING HEART T-LIGHT HOLDER | D23: 32 | E23: 40148.421 | F23: 10 AM | G23: 2.55 | H23: 13758 | I23: United Kingdom | J23: =D23*G23 -> 81.6
A24: 489504 | B24: 85083 | C24: KISS REINDEER SCANDINAVIAN STOCKING | D24: 6 | E24: 40148.465 | F24: 11 AM | G24: 2.55 | H24: 13916 | I24: United Kingdom | J24: =D24*G24 -> 15.3
A25: 489519 | B25: 22276 | C25: WASH BAG VINTAGE ROSE PAISLEY | D25: 6 | E25: 40148.484 | F25: 11 AM | G25: 2.55 | H25: 17700 | I25: United Kingdom | J25: =D25*G25 -> 15.3
A26: 489529 | B26: 22300 | C26: COFFEE MUG DOG + BALL DESIGN | D26: 6 | E26: 40148.494 | F26: 11 AM | G26: 2.55 | H26: 17984 | I26: United Kingdom | J26: =D26*G26 -> 15.3
A27: 489488 | B27: 84032A | C27: CHARLIE+LOLA PINK HOT WATER BOTTLE | D27: 1 | E27: 40148.458 | F27: 10 AM | G27: 2.95 | H27: 17238 | I27: United Kingdom | J27: =D27*G27 -> 2.95
A28: 489517 | B28: 16207A | C28: PINK STRAWBERRY HANDBAG | D28: 2 | E28: 40148.482 | F28: 11 AM | G28: 2.95 | H28: 16329 | I28: United Kingdom | J28: =D28*G28 -> 5.9
A29: 489545 | B29: 22113 | C29: GREY HEART HOT WATER BOTTLE | D29: 1 | E29: 40148.515 | F29: 12 PM | G29: 3.45 | H29: 17804 | I29: United Kingdom | J29: =D29*G29 -> 3.45
A30: 489537 | B30: 20967 | C30: GREY FLORAL FELTCRAFT SHOULDER BAG | D30: 2 | E30: 40148.51 | F30: 12 PM | G30: 3.75 | H30: 14040 | I30: United Kingdom | J30: =D30*G30 -> 7.5
A31: 489441 | B31: 22138 | C31: BAKING SET 9 PIECE RETROSPOT | D31: 6 | E31: 40148.406 | F31: 9 AM | G31: 4.25 | H31: 18087 | I31: United Kingdom | J31: =D31*G31 -> 25.5
A32: 489448 | B32: 20823 | C32: GOLD WINE GOBLET | D32: 48 | E32: 40148.429 | F32: 10 AM | G32: 4.25 | H32: 15413 | I32: United Kingdom | J32: =D32*G32 -> 204
A33: 489459 | B33: 90200E | C33: GREEN SWEETHEART BRACELET | D33: 3 | E33: 40148.447 | F33: 10 AM | G33: 4.25 | H33: 17592 | I33: United Kingdom | J33: =D33*G33 -> 12.75
A34: 489462 | B34: 90200E | C34: GREEN SWEETHEART BRACELET | D34: 3 | E34: 40148.451 | F34: 10 AM | G34: 4.25 | H34: 17592 | I34: United Kingdom | J34: =D34*G34 -> 12.75
A35: 489462 | B35: 90185C | C35: BLACK DIAMANTE EXPANDABLE RING | D35: 3 | E35: 40148.451 | F35: 10 AM | G35: 4.25 | H35: 17592 | I35: United Kingdom | J35: =D35*G35 -> 12.75
A36: 489503 | B36: 21540 | C36: DAIRY MAID CERAMIC BUTTER DISH | D36: 2 | E36: 40148.461 | F36: 11 AM | G36: 4.25 | H36: 16011 | I36: United Kingdom | J36: =D36*G36 -> 8.5
A37: 489530 | B37: 72803A | C37: ROSE SCENT CANDLE JEWELLED DRAWER | D37: 1 | E37: 40148.497 | F37: 11 AM | G37: 4.25 | H37: 14748 | I37: United Kingdom | J37: =D37*G37 -> 4.25
A38: 489439 | B38: 22138 | C38: BAKING SET 9 PIECE RETROSPOT | D38: 9 | E38: 40148.394 | F38: 9 AM | G38: 4.95 | H38: 12682 | I38: France | J38: =D38*G38 -> 44.55
A39: 489442 | B39: 22111 | C39: SCOTTIE DOG HOT WATER BOTTLE | D39: 3 | E39: 40148.407 | F39: 9 AM | G39: 4.95 | H39: 13635 | I39: United Kingdom | J39: =D39*G39 -> 14.85
A40: 489465 | B40: 21707 | C40: FOLDING UMBRELLA , BLACK/BLUE SPOT | D40: 12 | E40: 40148.453 | F40: 10 AM | G40: 4.95 | H40: 13767 | I40: United Kingdom | J40: =D40*G40 -> 59.4
...

Sheet Exploring Data Numerically
A2: Explore the data
A3: The dataset is now scrubbed and you can review it to gather insight. Refer back to the videos in this lesson for a refresher. Use the spreadsheet functions to explore the data, including:
A4: Calculating totals Price
A5: Calculating averages and findings medians of Price
A6: Finding maximum and minimum values of Price
A7: Determining correlations by finding the correlation coefficient (CORREL) b/w Price & Quantity & Invoice Date & Price
A10: Total Price | B10: =SUM('Clean Data'!G2:G46) -> 145.29
A11: Average Price | B11: =AVERAGE('Clean Data'!G2:G46) -> 3.2286667
A12: Median of Price | B12: =MEDIAN('Clean Data'!G2:G46) -> 2.55
A13: Maximum Price | B13: =MAX('Clean Data'!G:G) -> 12.75
A14: Minimum Price | B14: =MIN('Clean Data'!G:G) -> 0.55
A15: Correlation(Price & Quantity) | B15: =CORREL('Clean Data'!D2:D46,'Clean Data'!G2:G46) -> -0.13809823
A16: Correlation(Invoice Date & Price) | B16: =CORREL('Clean Data'!E2:E46,'Clean Data'!G2:G46) -> 0.10778925
A19: Key Insights:
A20: 1. Price Distribution
A21: Right-skewed distribution: Average ($3.2) > Median ($2.6)
A22: This means there are some high-priced outliers pulling the average up
A23: Most prices cluster around $2.1 or less
A25: 2. Price Range & Spread
A26: Wide range: $0.55 to $12.75 (12.20 range)
A28: 3. Correlation Analysis:
A29: Price vs. Quantity: -0.139
A30: Weak negative correlation
A31: As quantity increases, price tends to decrease slightly
A32: Confirms the demand curve relationship from your regression
... A36: Slight tendency for prices to increase over time, but not significant

Sheet Exploring Data Visually
A3: Time | B3: Sum of Revenue | J3: Country | K3: Count of Country
A4: 7 AM | B4: 140.4 | J4: Germany | K4: 1
A5: 9 AM | B5: 244.9 | J5: EIRE | K5: 1
A6: 10 AM | B6: 457 | J6: France | K6: 2
A7: 11 AM | B7: 1465.45 | J7: Australia | K7: 2
A8: 12 PM | B8: 27.1 | J8: United Kingdom | K8: 39
A9: Grand Total | B9: 2334.85 | J9: Grand Total | K9: 45
A23: Country | B23: Sum of Revenue | J23: Products | K23: Sum of Revenue
A24: EIRE | B24: 9 | J24: ASSORTED COLOUR BIRD ORNAMENT | K24: 1160
A25: Germany | B25: 15 | J25: GOLD WINE GOBLET | K25: 204
A26: Australia | B26: 27.6 | J26: RECORD FRAME 7" SINGLE SIZE | K26: 100.8
A27: France | B27: 50.5 | J27: PINK FAIRY CAKE CHILD'S APRON | K27: 82.5
A28: United Kingdom | B28: 2232.75 | J28: RED HANGING HEART T-LIGHT HOLDER | K28: 81.6
A29: Grand Total | B29: 2334.85 | J29: BAKING SET 9 PIECE RETROSPOT | K29: 70.05
J30: DOOR MAT BLACK FLOCK | K30: 59.5
J31: DOOR MAT FAIRY CAKE | K31: 59.5
J32: FOLDING UMBRELLA , BLACK/BLUE SPOT | K32: 59.4
J33: SET OF MEADOW FLOWER STICKERS | K33: 50.7
J34: Grand Total | K34: 1928.05
A43: Revenue & Customer Analysis Summary:
A44: 1. Revenue by Time of Day
A45: Peak: 12 PM ($1,400-1,600) & 11 AM ($1,200-1,400)
A46: Morning buildup from 7 AM to noon
A47: Action: Focus staffing/marketing on 11 AM - 12 PM window
A49: 2. Geographic Revenue Concentration
A50: UK dominates: 95%+ of total revenue ($2,232.75)
A51: International underperformance: France ($50), Germany ($28), Australia ($15), EIRE ($9)
A52: Risk: Extreme single-market dependency
A54: 3. Customer Distribution
A55: UK: 87% of customer base
A56: International: 13% spread across 4 markets
... A67: Opportunities: European expansion, peak hour optimization, category expansion
K80: 1. Geographic Concentration:
K81: UK dominates both customer count 87% of customers & by price
K82: Limited international presence: Germany (5%), France (4%), Australia & EIRE (2% each)
K83: Risk: Over-dependence on single market
K85: 2. Daily Sales Pattern:
K86: Peak at 12 PM (~65), second peak at 11 AM (~55)
K87: Morning buildup: Sales increase from 7 AM to noon
K88: Opportunity: Focus resources on 11 AM - 12 PM window
...

Sheet Model Data
B4: Linear Regression
B5: =LINEST('Clean Data'!G2:G46,'Clean Data'!D2:D46,TRUE,FALSE) -> -0.0029357247 | D5: =INDEX(LINEST('Clean Data'!G2:G46,'Clean Data'!D2:D46,TRUE,FALSE),1,2) -> 3.3123674
B8: So slope form is:
B9: y=-0.002936x+3.31
B11: let x=900
B12: =-0.002936*900+3.31 -> 0.6676
A21: Key Insights:
A22: 1. Price-Quantity Relationship
A23: Negative slope (-0.0029): As Quantity increases, Price decreases
A24: This is a typical demand curve - higher quantities correlate with lower prices
A26: 2. Economic Meaning:
A27: Intercept (3.3124): When Quantity = 0, the expected Price is ~3.31
A28: Slope (-0.0029): For every 1 unit increase in Quantity, Price decreases by 0.0029 units
A30: 3. Your Specific Calculation:
A31: For x = 900 (Quantity = 900):
A32: Your calculation shows Price ≈ 0.6676
A33: This means at 900 units, the expected price is about 0.67
